Workbook

Sheet Data
A1: sample_id | B1: hr_fft | C1: conf_fft | D1: peak_hz | E1: peak_ratio | F1: k_peaks | G1: hr_final | H1: conf_final | I1: mode | J1: s_motion | K1: s_freq | L1: motion_high | M1: freq_bad | N1: motion | O1: external_hr | P1: error_bpm | Q1: abs_error_bpm
A2: 471 | B2: 88.7 | C2: 0.9 | D2: 1.525 | E2: 2.97 | F2: 8 | G2: 88.7 | H2: 0.89 | I2: FREQ | J2: 0.98 | K2: 0.89 | L2: 0 | M2: 0 | N2: 154.1 | O2: 90 | P2: =G2-O2 -> -1.3 | Q2: =ABS(P2) -> 1.3
A3: 472 | B3: 90.4 | C3: 0.94 | D3: 1.546 | E3: 3.08 | F3: 8 | G3: 90.4 | H3: 0.91 | I3: FREQ | J3: 0.98 | K3: 0.91 | L3: 0 | M3: 0 | N3: 154.3 | O3: 90 | P3: =G3-O3 -> 0.4 | Q3: =ABS(P3) -> 0.4
A4: 473 | B4: 91.7 | C4: 0.97 | D4: 1.559 | E4: 3.21 | F4: 8 | G4: 91.7 | H4: 0.96 | I4: FREQ | J4: 0.98 | K4: 0.96 | L4: 0 | M4: 0 | N4: 231.4 | O4: 92 | P4: =G4-O4 -> -0.3 | Q4: =ABS(P4) -> 0.3
A5: 474 | B5: 92.3 | C5: 1 | D5: 1.549 | E5: 3.29 | F5: 8 | G5: 92.3 | H5: 1 | I5: FREQ | J5: 0.97 | K5: 1 | L5: 0 | M5: 0 | N5: 283.2 | O5: 92 | P5: =G5-O5 -> 0.3 | Q5: =ABS(P5) -> 0.3
A6: 475 | B6: 92.4 | C6: 1 | D6: 1.54 | E6: 3.41 | F6: 8 | G6: 92.4 | H6: 1 | I6: FREQ | J6: 0.97 | K6: 1 | L6: 0 | M6: 0 | N6: 311.4 | O6: 93 | P6: =G6-O6 -> -0.6 | Q6: =ABS(P6) -> 0.6
A7: 476 | B7: 92.6 | C7: 1 | D7: 1.553 | E7: 3.52 | F7: 8 | G7: 92.6 | H7: 0.94 | I7: FREQ | J7: 0.97 | K7: 0.94 | L7: 0 | M7: 0 | N7: 289 | O7: 93 | P7: =G7-O7 -> -0.4 | Q7: =ABS(P7) -> 0.4
A8: 477 | B8: 93.2 | C8: 1 | D8: 1.57 | E8: 3.4 | F8: 8 | G8: 93.2 | H8: 0.99 | I8: FREQ | J8: 0.97 | K8: 0.99 | L8: 0 | M8: 0 | N8: 338 | O8: 93 | P8: =G8-O8 -> 0.2 | Q8: =ABS(P8) -> 0.2
A9: 478 | B9: 93.4 | C9: 0.94 | D9: 1.558 | E9: 3.1 | F9: 8 | G9: 93.4 | H9: 0.92 | I9: FREQ | J9: 0.96 | K9: 0.92 | L9: 0 | M9: 0 | N9: 447.4 | O9: 93 | P9: =G9-O9 -> 0.4 | Q9: =ABS(P9) -> 0.4
A10: 479 | B10: 92.9 | C10: 0.92 | D10: 1.532 | E10: 3.05 | F10: 8 | G10: 92.9 | H10: 0.9 | I10: FREQ | J10: 0.95 | K10: 0.9 | L10: 0 | M10: 0 | N10: 516.2 | O10: 93 | P10: =G10-O10 -> -0.1 | Q10: =ABS(P10) -> 0.1
A11: 480 | B11: 92 | C11: 0.9 | D11: 1.51 | E11: 2.95 | F11: 8 | G11: 92 | H11: 0.86 | I11: FREQ | J11: 0.96 | K11: 0.86 | L11: 0 | M11: 0 | N11: 406.9 | O11: 93 | P11: =G11-O11 -> -1 | Q11: =ABS(P11) -> 1
A12: 482 | B12: 90.2 | C12: 0.77 | D12: 1.494 | E12: 2.53 | F12: 8 | G12: 90.2 | H12: 0.76 | I12: FREQ | J12: 0.96 | K12: 0.76 | L12: 0 | M12: 0 | N12: 356.5 | O12: 91 | P12: =G12-O12 -> -0.8 | Q12: =ABS(P12) -> 0.8
A13: 483 | B13: 90.4 | C13: 0.85 | D13: 1.514 | E13: 2.8 | F13: 8 | G13: 90.4 | H13: 0.77 | I13: FREQ | J13: 0.97 | K13: 0.77 | L13: 0 | M13: 0 | N13: 345.2 | O13: 90 | P13: =G13-O13 -> 0.4 | Q13: =ABS(P13) -> 0.4
... A61: 535 | B61: 94 | C61: 0.99 | D61: 1.572 | E61: 3.27 | F61: 8 | G61: 94 | H61: 0.94 | I61: FREQ | J61: 0.97 | K61: 0.94 | L61: 0 | M61: 0 | N61: 286.8 | O61: 95 | P61: =G61-O61 -> -1 | Q61: =ABS(P61) -> 1

Sheet Summary
A1: No Motion Final HR Performance Analysis | D1: Notes
A2: Metric | B2: Value | D2: Error is calculated as Final HR minus External HR.
A3: Samples | B3: =COUNTA(Data!G2:G61) -> 60 | D3: Absolute error is the absolute difference between Final HR and External HR.
A4: MAE (BPM) | B4: =AVERAGE(Data!Q2:Q61) -> 0.70833333 | D4: Hold Mode (%) is based on rows where mode = 0.
A5: RMSE (BPM) | B5: =SQRT(AVERAGE(Data!P2:P61^2)) -> 0.3
A6: Max Error (BPM) | B6: =MAX(Data!Q2:Q61) -> 2.2
A7: HR Std Dev (BPM) | B7: =STDEV(C38:C97) -> 1.6886954
A8: Hold Mode (%) | B8: =COUNTIF(Data!I2:I61,"0")/COUNTA(Data!I2:I61) -> 0
A9: Mean Confidence | B9: =AVERAGE(Data!H2:H61) -> 0.82183333
A12: Sample | B12: External HR | C12: Final HR | D12: Absolute Error
A13: 1 | B13: =Data!#REF! -> #REF! | C13: =Data!#REF! -> #REF! | D13: =Data!#REF! -> #REF!
A14: 2 | B14: =Data!#REF! -> #REF! | C14: =Data!#REF! -> #REF! | D14: =Data!#REF! -> #REF!
A15: 3 | B15: =Data!#REF! -> #REF! | C15: =Data!#REF! -> #REF! | D15: =Data!#REF! -> #REF!
A16: 4 | B16: =Data!#REF! -> #REF! | C16: =Data!#REF! -> #REF! | D16: =Data!#REF! -> #REF!
A17: 5 | B17: =Data!#REF! -> #REF! | C17: =Data!#REF! -> #REF! | D17: =Data!#REF! -> #REF!
A18: 6 | B18: =Data!#REF! -> #REF! | C18: =Data!#REF! -> #REF! | D18: =Data!#REF! -> #REF!
A19: 7 | B19: =Data!#REF! -> #REF! | C19: =Data!#REF! -> #REF! | D19: =Data!#REF! -> #REF!
A20: 8 | B20: =Data!#REF! -> #REF! | C20: =Data!#REF! -> #REF! | D20: =Data!#REF! -> #REF!
A21: 9 | B21: =Data!#REF! -> #REF! | C21: =Data!#REF! -> #REF! | D21: =Data!#REF! -> #REF!
A22: 10 | B22: =Data!#REF! -> #REF! | C22: =Data!#REF! -> #REF! | D22: =Data!#REF! -> #REF!
A23: 11 | B23: =Data!#REF! -> #REF! | C23: =Data!#REF! -> #REF! | D23: =Data!#REF! -> #REF!
A24: 12 | B24: =Data!#REF! -> #REF! | C24: =Data!#REF! -> #REF! | D24: =Data!#REF! -> #REF!
... A37: 25 | B37: =Data!#REF! -> #REF! | C37: =Data!#REF! -> #REF! | D37: =Data!#REF! -> #REF!
A38: 26 | B38: =Data!O2 -> 90 | C38: =Data!G2 -> 88.7 | D38: =Data!Q2 -> 1.3
A39: 27 | B39: =Data!O3 -> 90 | C39: =Data!G3 -> 90.4 | D39: =Data!Q3 -> 0.4
A40: 28 | B40: =Data!O4 -> 92 | C40: =Data!G4 -> 91.7 | D40: =Data!Q4 -> 0.3
A41: 29 | B41: =Data!O5 -> 92 | C41: =Data!G5 -> 92.3 | D41: =Data!Q5 -> 0.3
A42: 30 | B42: =Data!O6 -> 93 | C42: =Data!G6 -> 92.4 | D42: =Data!Q6 -> 0.6
A43: 31 | B43: =Data!O7 -> 93 | C43: =Data!G7 -> 92.6 | D43: =Data!Q7 -> 0.4
A44: 32 | B44: =Data!O8 -> 93 | C44: =Data!G8 -> 93.2 | D44: =Data!Q8 -> 0.2
A45: 33 | B45: =Data!O9 -> 93 | C45: =Data!G9 -> 93.4 | D45: =Data!Q9 -> 0.4
A46: 34 | B46: =Data!O10 -> 93 | C46: =Data!G10 -> 92.9 | D46: =Data!Q10 -> 0.1
A47: 35 | B47: =Data!O11 -> 93 | C47: =Data!G11 -> 92 | D47: =Data!Q11 -> 1
A48: 36 | B48: =Data!O12 -> 91 | C48: =Data!G12 -> 90.2 | D48: =Data!Q12 -> 0.8
A49: 37 | B49: =Data!O13 -> 90 | C49: =Data!G13 -> 90.4 | D49: =Data!Q13 -> 0.4
... A97: 85 | B97: =Data!O61 -> 95 | C97: =Data!G61 -> 94 | D97: =Data!Q61 -> 1
A98: 86 | B98: =Data!#REF! -> #REF! | C98: =Data!#REF! -> #REF! | D98: =Data!#REF! -> #REF!
A99: 87 | B99: =Data!#REF! -> #REF! | C99: =Data!#REF! -> #REF! | D99: =Data!#REF! -> #REF!
A100: 88 | B100: =Data!#REF! -> #REF! | C100: =Data!#REF! -> #REF! | D100: =Data!#REF! -> #REF!
A101: 89 | B101: =Data!#REF! -> #REF! | C101: =Data!#REF! -> #REF! | D101: =Data!#REF! -> #REF!
...
